<?xml version='1.0'?>
<sdf version='1.7'>
  <model name='car'>
    <model name='car'>
      <link name='link_0'>
        <inertial>
          <mass>0.121386</mass>
          <inertia>
            <ixx>0.00292212</ixx>
            <iyy>0.0107847</iyy>
            <izz>0.0123684</izz>
            <ixy>0</ixy>
            <ixz>0</ixz>
            <iyz>0</iyz>
          </inertia>
        </inertial>
        <pose>0.06373 0.001272 0.010392 0 -0 0</pose>
        <visual name='visual'>
          <geometry>
            <box>
              <size>1 0.5 0.15</size>
            </box>
          </geometry>
        </visual>
        <collision name='collision'>
          <geometry>
            <box>
              <size>1 0.5 0.15</size>
            </box>
          </geometry>
        </collision>
      </link>
      <link name='link_1'>
        <inertial>
          <mass>1</mass>
          <inertia>
            <ixx>0.145833</ixx>
            <iyy>0.145833</iyy>
            <izz>0.125</izz>
            <ixy>0</ixy>
            <ixz>0</ixz>
            <iyz>0</iyz>
          </inertia>
        </inertial>
        <pose>-0.185439 -0.266829 0.010392 0 -0 0</pose>
        <visual name='visual'>
          <pose>0 0 0 1.57 -0 0</pose>
          <geometry>
            <cylinder>
              <radius>0.12</radius>
              <length>0.035</length>
            </cylinder>
          </geometry>
        </visual>
        <collision name='collision'>
          <pose>0 0 0 1.57 -0 0</pose>
          <geometry>
            <cylinder>
              <radius>0.12</radius>
              <length>0.035</length>
            </cylinder>
          </geometry>
        </collision>
      </link>
      <link name='link_1_clone_0'>
        <inertial>
          <mass>1</mass>
          <inertia>
            <ixx>0.145833</ixx>
            <iyy>0.145833</iyy>
            <izz>0.125</izz>
            <ixy>0</ixy>
            <ixz>0</ixz>
            <iyz>0</iyz>
          </inertia>
        </inertial>
        <pose>-0.185439 0.268171 0.010392 0 -0 0</pose>
        <visual name='visual'>
          <pose>0 0 0 1.57 -0 0</pose>
          <geometry>
            <cylinder>
              <radius>0.12</radius>
              <length>0.035</length>
            </cylinder>
          </geometry>
        </visual>
        <collision name='collision'>
          <pose>0 0 0 1.57 -0 0</pose>
          <geometry>
            <cylinder>
              <radius>0.12</radius>
              <length>0.035</length>
            </cylinder>
          </geometry>
        </collision>
      </link>
      <link name='link_2'>
        <inertial>
          <mass>0.00215059</mass>
          <inertia>
            <ixx>3.58e-06</ixx>
            <iyy>3.58e-06</iyy>
            <izz>3.58e-06</izz>
            <ixy>0</ixy>
            <ixz>0</ixz>
            <iyz>0</iyz>
          </inertia>
        </inertial>
        <pose>0.307147 -0.002614 -0.031178 0 -0 0</pose>
        <visual name='visual'>
          <geometry>
            <sphere>
              <radius>0.08</radius>
            </sphere>
          </geometry>
        </visual>
        <collision name='collision'>
          <geometry>
            <sphere>
              <radius>0.08</radius>
            </sphere>
          </geometry>
        </collision>
      </link>
      <joint name='right_wheel_joint' type='revolute'>
        <parent>link_0</parent>
        <child>link_1</child>
        <pose>0 0 0 0 -0 0</pose>
        <axis>
          <xyz>1 0 0</xyz>
          <limit>
            <lower>-1.79769e+308</lower>
            <upper>1.79769e+308</upper>
          </limit>
        </axis>
      </joint>
      <joint name='left_wheel_joint' type='revolute'>
        <parent>link_0</parent>
        <child>link_1_clone_0</child>
        <pose>0 0 0 0 -0 0</pose>
        <axis>
          <xyz>1 0 0</xyz>
          <limit>
            <lower>-1.79769e+308</lower>
            <upper>1.79769e+308</upper>
          </limit>
        </axis>
      </joint>
      <pose>-0.195382 0.001523 -0.042167 0 -0 0</pose>
    </model>
    <model name='depth_camera'>
      <link name='link'>
        <pose>0 0 0.05 0 -0 0</pose>
        <inertial>
          <mass>0.1</mass>
          <inertia>
            <ixx>0.000166667</ixx>
            <iyy>0.000166667</iyy>
            <izz>0.000166667</izz>
            <ixy>0</ixy>
            <ixz>0</ixz>
            <iyz>0</iyz>
          </inertia>
        </inertial>
        <collision name='collision'>
          <geometry>
            <box>
              <size>0.1 0.1 0.1</size>
            </box>
          </geometry>
        </collision>
        <visual name='visual'>
          <geometry>
            <box>
              <size>0.1 0.1 0.1</size>
            </box>
          </geometry>
        </visual>
        <sensor name='camera' type='depth'>
          <camera>
            <horizontal_fov>1.047</horizontal_fov>
            <image>
              <width>320</width>
              <height>240</height>
            </image>
            <clip>
              <near>0.1</near>
              <far>100</far>
            </clip>
          </camera>
          <always_on>1</always_on>
          <update_rate>30</update_rate>
          <visualize>1</visualize>
        </sensor>
      </link>
      <pose>0.195381 -0.001523 0.042167 0 -0 0</pose>
    </model>
    <joint name='depth_cam_joint' type='fixed'>
      <parent>car::link_0</parent>
      <child>depth_camera::link</child>
      <pose>0 0 0 0 -0 0</pose>
      <physics>
        <ode>
          <limit>
            <cfm>0</cfm>
            <erp>0.2</erp>
          </limit>
          <suspension>
            <cfm>0</cfm>
            <erp>0.2</erp>
          </suspension>
        </ode>
      </physics>
    </joint>
    <static>0</static>
    <allow_auto_disable>1</allow_auto_disable>
    <plugin name='follower' filename='libFollowerPlugin.so'/>
  </model>
</sdf>
